<?xml version="1.0" ?>
<!-- =================================================================================== -->
<!-- |    This document was autogenerated by xacro from /workspaces/roboeagles2024/src/edna_description/urdf/robots/edna.urdf.xacro | -->
<!-- |    EDITING THIS FILE BY HAND IS NOT RECOMMENDED                                 | -->
<!-- =================================================================================== -->
<robot name="edna">
  <!-- Specify some standard inertial calculations https://en.wikipedia.org/wiki/List_of_moments_of_inertia -->
  <!-- These make use of xacro's mathematical functionality -->
  <material name="black">
    <color rgba="0.0 0.0 0.0 1.0"/>
  </material>
  <material name="blue">
    <color rgba="0.13725490196078433 0.43137254901960786 0.5882352941176471 1.0"/>
  </material>
  <material name="dark-blue">
    <color rgba="0.0 0.0 0.5450980392156862 1.0"/>
  </material>
  <material name="green">
    <color rgba="0.0 0.8 0.0 1.0"/>
  </material>
  <material name="ghost">
    <color rgba="0.0 0.8 0.0 0.5"/>
  </material>
  <material name="grey">
    <color rgba="0.2 0.2 0.2 1.0"/>
  </material>
  <material name="yellow">
    <color rgba="1.0 0.8431372549019608 0.0 1"/>
  </material>
  <material name="orange">
    <color rgba="0.9529411764705882 0.5294117647058824 0.1843137254901961 1"/>
  </material>
  <material name="brown">
    <color rgba="0.8705882352941177 0.8117647058823529 0.7647058823529411 1.0"/>
  </material>
  <material name="red">
    <color rgba="0.8 0.0 0.0 1.0"/>
  </material>
  <material name="white">
    <color rgba="1.0 1.0 1.0 1.0"/>
  </material>
  <material name="silver">
    <color rgba="0.700 0.700 0.700 1.000"/>
  </material>
  <material name="zed2i_mat">
    <color rgba="0.25 0.25 0.25 0.99"/>
  </material>
  <!-- Made up values, replace with real ones later. -->
  <!-- X IS FORWARD -->
  <!-- Y IS LEFT -->
  <!-- Z IS UP -->
  <!-- Chassis -->
  <link name="base_link">
    <!-- Set mass to 0 and give a valid inertia tensor of 0 -->
    <inertial>
      <mass value="0.0"/>
      <origin rpy="0 0 0" xyz="0 0 0"/>
      <inertia ixx="0.0" ixy="0.0" ixz="0.0" iyy="0.0" iyz="0.0" izz="0.0"/>
    </inertial>
  </link>
  <link name="swerve_chassis_link">
    <inertial>
      <origin rpy="0 0 0" xyz="0 0 0"/>
      <mass value="11.7934"/>
      <inertia ixx="0.43115569682666666" ixy="0.0" ixz="0.0" iyy="0.43115569682666666" iyz="0.0" izz="0.8572389736906666"/>
    </inertial>
    <visual>
      <origin rpy="0 0 1.5707963267948966" xyz="0 0 0.0254"/>
      <geometry>
        <mesh filename="package://edna_description/meshes/RiftChassis.stl" scale="0.001 0.001 0.001"/>
      </geometry>
      <material name="red"/>
    </visual>
    <collision>
      <origin rpy="0 0 0" xyz="0 0 0"/>
      <geometry>
        <box size="0.6604 0.6604 0.0508 "/>
      </geometry>
    </collision>
  </link>
  <link name="swerve_bumper_link">
    <inertial>
      <origin rpy="0 0 0" xyz="0 0 0.0762"/>
      <mass value="6.80388555"/>
      <inertia ixx="0.3383645992775125" ixy="0.0" ixz="0.0" iyy="0.3383645992775125" iyz="0.0" izz="0.6584392202157"/>
    </inertial>
    <visual>
      <origin rpy="0 0 0" xyz="0 0 0.1397"/>
      <geometry>
        <mesh filename="package://edna_description/meshes/Bumper.stl" scale="0.001 0.001 0.001"/>
      </geometry>
      <material name="dark-blue"/>
    </visual>
    <collision>
      <origin rpy="0 0 0" xyz="0 0 0.0762"/>
      <geometry>
        <box size="0.762 0.762 0.127 "/>
      </geometry>
    </collision>
  </link>
  <joint name="swerve_chassis_joint" type="fixed">
    <parent link="base_link"/>
    <child link="swerve_chassis_link"/>
    <origin rpy="0 0 0" xyz="0 0 0"/>
  </joint>
  <joint name="swerve_bumper_joint" type="fixed">
    <parent link="base_link"/>
    <child link="swerve_bumper_link"/>
    <origin rpy="0 0 0" xyz="0 0 0"/>
  </joint>
  <link name="front_left_axle_link">
    <visual>
      <origin rpy="3.141592653589793 0 1.5707963267948966" xyz="0 0 0"/>
      <geometry>
        <mesh filename="package://edna_description/meshes/SwerveAxle.stl" scale="0.001 0.001 0.001"/>
      </geometry>
      <material name="blue"/>
    </visual>
    <inertial>
      <origin rpy="0 0 0" xyz="0 0 -0.015"/>
      <mass value="0.23739"/>
      <inertia ixx="0.000166173" ixy="0.0" ixz="0.0" iyy="0.000166173" iyz="0.0" izz="0.00029673750000000005"/>
    </inertial>
  </link>
  <joint name="front_left_axle_joint" type="continuous">
    <parent link="swerve_chassis_link"/>
    <child link="front_left_axle_link"/>
    <origin rpy="0 0 0" xyz="0.261523 0.261523 0.06905599999999999"/>
    <axis xyz="0 0 -1"/>
    <dynamics friction="0.1"/>
  </joint>
  <link name="front_left_wheel_link">
    <visual>
      <origin rpy="1.5707963267948966 0 -0.7853981633974483" xyz="0 0.022 0"/>
      <geometry>
        <mesh filename="package://edna_description/meshes/SwerveWheel.stl" scale="0.001 0.001 0.001"/>
      </geometry>
      <material name="yellow"/>
    </visual>
    <collision>
      <origin rpy="1.5707963267948966 0 0" xyz="0 0 0"/>
      <geometry>
        <cylinder length="0.0381" radius="0.0508"/>
        <!-- <mesh filename="package://edna_description/meshes/SwerveWheel.stl" scale="0.001 0.001 0.001" /> -->
      </geometry>
    </collision>
    <inertial>
      <origin rpy="1.5707963267948966 0 0" xyz="0 0 0"/>
      <mass value="0.23133211"/>
      <inertia ixx="0.00017722989110402498" ixy="0.0" ixz="0.0" iyy="0.00017722989110402498" iyz="0.0" izz="0.0002984924481752"/>
    </inertial>
  </link>
  <joint name="front_left_wheel_joint" type="continuous">
    <parent link="front_left_axle_link"/>
    <child link="front_left_wheel_link"/>
    <origin rpy="0 0 0" xyz="0 0 -0.063"/>
    <axis xyz="0 1 0"/>
    <dynamics friction="0.1"/>
  </joint>
  <link name="front_right_axle_link">
    <visual>
      <origin rpy="3.141592653589793 0 1.5707963267948966" xyz="0 0 0"/>
      <geometry>
        <mesh filename="package://edna_description/meshes/SwerveAxle.stl" scale="0.001 0.001 0.001"/>
      </geometry>
      <material name="blue"/>
    </visual>
    <inertial>
      <origin rpy="0 0 0" xyz="0 0 -0.015"/>
      <mass value="0.23739"/>
      <inertia ixx="0.000166173" ixy="0.0" ixz="0.0" iyy="0.000166173" iyz="0.0" izz="0.00029673750000000005"/>
    </inertial>
  </link>
  <joint name="front_right_axle_joint" type="continuous">
    <parent link="swerve_chassis_link"/>
    <child link="front_right_axle_link"/>
    <origin rpy="0 0 0" xyz="0.261523 -0.261523 0.06905599999999999"/>
    <axis xyz="0 0 -1"/>
    <dynamics friction="0.1"/>
  </joint>
  <link name="front_right_wheel_link">
    <visual>
      <origin rpy="1.5707963267948966 0 -0.7853981633974483" xyz="0 0.022 0"/>
      <geometry>
        <mesh filename="package://edna_description/meshes/SwerveWheel.stl" scale="0.001 0.001 0.001"/>
      </geometry>
      <material name="yellow"/>
    </visual>
    <collision>
      <origin rpy="1.5707963267948966 0 0" xyz="0 0 0"/>
      <geometry>
        <cylinder length="0.0381" radius="0.0508"/>
        <!-- <mesh filename="package://edna_description/meshes/SwerveWheel.stl" scale="0.001 0.001 0.001" /> -->
      </geometry>
    </collision>
    <inertial>
      <origin rpy="1.5707963267948966 0 0" xyz="0 0 0"/>
      <mass value="0.23133211"/>
      <inertia ixx="0.00017722989110402498" ixy="0.0" ixz="0.0" iyy="0.00017722989110402498" iyz="0.0" izz="0.0002984924481752"/>
    </inertial>
  </link>
  <joint name="front_right_wheel_joint" type="continuous">
    <parent link="front_right_axle_link"/>
    <child link="front_right_wheel_link"/>
    <origin rpy="0 0 0" xyz="0 0 -0.063"/>
    <axis xyz="0 1 0"/>
    <dynamics friction="0.1"/>
  </joint>
  <link name="rear_left_axle_link">
    <visual>
      <origin rpy="3.141592653589793 0 1.5707963267948966" xyz="0 0 0"/>
      <geometry>
        <mesh filename="package://edna_description/meshes/SwerveAxle.stl" scale="0.001 0.001 0.001"/>
      </geometry>
      <material name="blue"/>
    </visual>
    <inertial>
      <origin rpy="0 0 0" xyz="0 0 -0.015"/>
      <mass value="0.23739"/>
      <inertia ixx="0.000166173" ixy="0.0" ixz="0.0" iyy="0.000166173" iyz="0.0" izz="0.00029673750000000005"/>
    </inertial>
  </link>
  <joint name="rear_left_axle_joint" type="continuous">
    <parent link="swerve_chassis_link"/>
    <child link="rear_left_axle_link"/>
    <origin rpy="0 0 0" xyz="-0.261523 0.261523 0.06905599999999999 "/>
    <axis xyz="0 0 -1"/>
    <dynamics friction="0.1"/>
  </joint>
  <link name="rear_left_wheel_link">
    <visual>
      <origin rpy="1.5707963267948966 0 -0.7853981633974483" xyz="0 0.022 0"/>
      <geometry>
        <mesh filename="package://edna_description/meshes/SwerveWheel.stl" scale="0.001 0.001 0.001"/>
      </geometry>
      <material name="yellow"/>
    </visual>
    <collision>
      <origin rpy="1.5707963267948966 0 0" xyz="0 0 0"/>
      <geometry>
        <cylinder length="0.0381" radius="0.0508"/>
        <!-- <mesh filename="package://edna_description/meshes/SwerveWheel.stl" scale="0.001 0.001 0.001" /> -->
      </geometry>
    </collision>
    <inertial>
      <origin rpy="1.5707963267948966 0 0" xyz="0 0 0"/>
      <mass value="0.23133211"/>
      <inertia ixx="0.00017722989110402498" ixy="0.0" ixz="0.0" iyy="0.00017722989110402498" iyz="0.0" izz="0.0002984924481752"/>
    </inertial>
  </link>
  <joint name="rear_left_wheel_joint" type="continuous">
    <parent link="rear_left_axle_link"/>
    <child link="rear_left_wheel_link"/>
    <origin rpy="0 0 0" xyz="0 0 -0.063"/>
    <axis xyz="0 1 0"/>
    <dynamics friction="0.1"/>
  </joint>
  <link name="rear_right_axle_link">
    <visual>
      <origin rpy="3.141592653589793 0 1.5707963267948966" xyz="0 0 0"/>
      <geometry>
        <mesh filename="package://edna_description/meshes/SwerveAxle.stl" scale="0.001 0.001 0.001"/>
      </geometry>
      <material name="blue"/>
    </visual>
    <inertial>
      <origin rpy="0 0 0" xyz="0 0 -0.015"/>
      <mass value="0.23739"/>
      <inertia ixx="0.000166173" ixy="0.0" ixz="0.0" iyy="0.000166173" iyz="0.0" izz="0.00029673750000000005"/>
    </inertial>
  </link>
  <joint name="rear_right_axle_joint" type="continuous">
    <parent link="swerve_chassis_link"/>
    <child link="rear_right_axle_link"/>
    <origin rpy="0 0 0" xyz="-0.261523 -0.261523 0.06905599999999999"/>
    <axis xyz="0 0 -1"/>
    <dynamics friction="0.1"/>
  </joint>
  <link name="rear_right_wheel_link">
    <visual>
      <origin rpy="1.5707963267948966 0 -0.7853981633974483" xyz="0 0.022 0"/>
      <geometry>
        <mesh filename="package://edna_description/meshes/SwerveWheel.stl" scale="0.001 0.001 0.001"/>
      </geometry>
      <material name="yellow"/>
    </visual>
    <collision>
      <origin rpy="1.5707963267948966 0 0" xyz="0 0 0"/>
      <geometry>
        <cylinder length="0.0381" radius="0.0508"/>
        <!-- <mesh filename="package://edna_description/meshes/SwerveWheel.stl" scale="0.001 0.001 0.001" /> -->
      </geometry>
    </collision>
    <inertial>
      <origin rpy="1.5707963267948966 0 0" xyz="0 0 0"/>
      <mass value="0.23133211"/>
      <inertia ixx="0.00017722989110402498" ixy="0.0" ixz="0.0" iyy="0.00017722989110402498" iyz="0.0" izz="0.0002984924481752"/>
    </inertial>
  </link>
  <joint name="rear_right_wheel_joint" type="continuous">
    <parent link="rear_right_axle_link"/>
    <child link="rear_right_wheel_link"/>
    <origin rpy="0 0 0" xyz="0 0 -0.063"/>
    <axis xyz="0 1 0"/>
    <dynamics friction="0.1"/>
  </joint>
  <!-- Sensors -->
  <!-- <xacro:zed_camera prefix="zed2i" model="zed2i" parent="swerve_chassis_link">
    <origin xyz="${cam_pos}" rpy="0 0 0" />
  </xacro:zed_camera> -->
  <!-- <xacro:lidar prefix="lidar" parent="swerve_chassis_link" radius="0.035" length="0.025">
    <origin xyz="${lidar_pos}" rpy="0 0 0" />
  </xacro:lidar> -->
  <!-- Arm -->
  <!-- <xacro:property name="elevator_leg_z" value="0.527"/>
  <xacro:elevator_leg prefix="arm" parent="swerve_chassis_link">
    <origin xyz = "0.1905 0 ${elevator_leg_z/2 + 0.03}" rpy = "0 0 0"/>
  </xacro:elevator_leg>

  <xacro:back_leg prefix="arm" parent="swerve_chassis_link">
    <origin xyz = "-${chassis_length/2 - each_leg_width * 2} 0 ${chassis_height}" rpy = "0 0 0" />
  </xacro:back_leg> -->
  <!--Elevator-->
  <!-- <xacro:elevator prefix="elevator" parent="arm_back_leg_link">
    <origin xyz = "-.03 -${elevator_middle_distance / 2} ${back_leg_height - .0215}" rpy = "0 0 0" />
  </xacro:elevator> -->
  <!-- Top Slider + Gripper -->
  <!-- <xacro:property name= "slider_pos" value = "0.330 ${elevator_middle_distance / 2} ${slider_block_height/2}" />
  <xacro:slider prefix="top" parent="elevator_outer_2_link">
    <origin xyz = "${slider_pos}" rpy = "0 0 0" />
  </xacro:slider> -->
  <ros2_control name="swerve_drive" type="system">
    <!-- USING A SINGLE HARDWARE INTERFACE TO REDUCE DDS AND THREAD LOAD ON RIO -->
    <hardware>
      <plugin>swerve_hardware/IsaacDriveHardware</plugin>
      <param name="example_param_hw_start_duration_sec">3.0</param>
      <param name="example_param_hw_stop_duration_sec">3.0</param>
    </hardware>
    <!-- DRIVE TRAIN COMPONENTS -->
    <joint name="front_right_wheel_joint">
      <command_interface name="velocity"/>
      <state_interface name="position"/>
      <state_interface name="velocity"/>
    </joint>
    <joint name="rear_left_wheel_joint">
      <command_interface name="velocity"/>
      <state_interface name="position"/>
      <state_interface name="velocity"/>
    </joint>
    <joint name="front_left_wheel_joint">
      <command_interface name="velocity"/>
      <state_interface name="position"/>
      <state_interface name="velocity"/>
    </joint>
    <joint name="rear_right_wheel_joint">
      <command_interface name="velocity"/>
      <state_interface name="position"/>
      <state_interface name="velocity"/>
    </joint>
    <joint name="front_right_axle_joint">
      <command_interface name="position"/>
      <state_interface name="position"/>
      <state_interface name="velocity"/>
    </joint>
    <joint name="rear_left_axle_joint">
      <command_interface name="position"/>
      <state_interface name="position"/>
      <state_interface name="velocity"/>
    </joint>
    <joint name="front_left_axle_joint">
      <command_interface name="position"/>
      <state_interface name="position"/>
      <state_interface name="velocity"/>
    </joint>
    <joint name="rear_right_axle_joint">
      <command_interface name="position"/>
      <state_interface name="position"/>
      <state_interface name="velocity"/>
    </joint>
    <!-- ARM COMPONENTS -->
    <joint name="arm_roller_bar_joint">
      <command_interface name="position">
        <param name="min">0</param>
        <param name="max">0.07</param>
      </command_interface>
      <state_interface name="position"/>
      <state_interface name="velocity"/>
      <param name="arm_group">true</param>
    </joint>
    <joint name="elevator_outer_1_joint">
      <command_interface name="position">
        <param name="min">-1</param>
        <param name="max">1</param>
      </command_interface>
      <state_interface name="position"/>
      <state_interface name="velocity"/>
      <param name="arm_group">true</param>
      <param name="mimic">arm_roller_bar_joint</param>
      <param name="multiplier">1.8</param>
    </joint>
    <joint name="elevator_center_joint">
      <command_interface name="position">
        <param name="min">0</param>
        <param name="max">0.56</param>
      </command_interface>
      <state_interface name="position"/>
      <state_interface name="velocity"/>
      <param name="arm_group">true</param>
    </joint>
    <joint name="elevator_outer_2_joint">
      <command_interface name="position">
        <param name="min">-1</param>
        <param name="max">1</param>
      </command_interface>
      <state_interface name="position"/>
      <state_interface name="velocity"/>
      <param name="mimic">elevator_center_joint</param>
      <param name="multiplier">1.0</param>
    </joint>
    <joint name="top_slider_joint">
      <command_interface name="position">
        <param name="min">0</param>
        <param name="max">0.30</param>
      </command_interface>
      <state_interface name="position"/>
      <state_interface name="velocity"/>
      <param name="arm_group">true</param>
      <param name="primary">true</param>
    </joint>
    <joint name="top_gripper_left_arm_joint">
      <command_interface name="position">
        <param name="min">0</param>
        <param name="max">0.90</param>
      </command_interface>
      <state_interface name="position"/>
      <state_interface name="velocity"/>
      <param name="arm_group">true</param>
    </joint>
    <joint name="top_gripper_right_arm_joint">
      <command_interface name="position">
        <param name="min">-1</param>
        <param name="max">1</param>
      </command_interface>
      <state_interface name="position"/>
      <state_interface name="velocity"/>
      <param name="arm_grouping">true</param>
      <param name="mimic">top_gripper_left_arm_joint</param>
      <param name="multiplier">1.0</param>
    </joint>
    <joint name="bottom_intake_joint">
      <command_interface name="position">
        <param name="min">0</param>
        <param name="max">1.5207963267948965</param>
      </command_interface>
      <state_interface name="position"/>
      <state_interface name="velocity"/>
      <param name="arm_group">true</param>
      <param name="primary">true</param>
    </joint>
  </ros2_control>
</robot>
